Workbook

Sheet Assumption Sheet
B1: Historical Results | H1: Forecast Period
C3: 2021A | D3: 2022A | E3: 2023A | F3: 2024A | G3: 2025A | H3: 2026F | I3: 2027F | J3: 2028F | K3: 2029F | L3: 2030F
A4: Assumptions&Drivers | C4: =C3 -> 2021A | D4: =D3 -> 2022A | E4: =E3 -> 2023A | F4: =F3 -> 2024A | G4: =G3 -> 2025A | H4: =H3 -> 2026F | I4: =I3 -> 2027F | J4: =J3 -> 2028F | ... L4: =L3 -> 2030F
A5: Income Statement Assumptions
A6: Revenue Growth % | C6: - | D6: =('Data Sheet'!D14-'Data Sheet'!C14)/'Data Sheet'!C14 -> 0.11520796 | E6: =('Data Sheet'!E14-'Data Sheet'!D14)/'Data Sheet'!D14 -> 0.15509286 | F6: =('Data Sheet'!F14-'Data Sheet'!E14)/'Data Sheet'!E14 -> 0.021723341 | G6: =('Data Sheet'!G14-'Data Sheet'!F14)/'Data Sheet'!F14 -> -0.0091766835 | H6: =$D$29 -> 0.06 | I6: =$D$29 -> 0.06 | J6: =$D$29 -> 0.06 | K6: =$D$29 -> 0.06 | L6: =$D$29 -> 0.06
A7: Cost of Goods Sold (% of Revenue) | C7: ='Data Sheet'!C15/'Data Sheet'!C14 -> 0.5 | D7: ='Data Sheet'!D15/'Data Sheet'!D14 -> 0.5 | E7: ='Data Sheet'!E15/'Data Sheet'!E14 -> 0.5 | F7: ='Data Sheet'!F15/'Data Sheet'!F14 -> 0.5 | G7: ='Data Sheet'!G15/'Data Sheet'!G14 -> 0.5 | H7: =$D$35 -> 0.5 | I7: =$D$35 -> 0.5 | J7: =$D$35 -> 0.5 | K7: =$D$35 -> 0.5 | L7: =$D$35 -> 0.5
A8: gross profit Mrgin % | C8: ='Data Sheet'!C16/'Data Sheet'!C14 -> 0.5 | D8: ='Data Sheet'!D16/'Data Sheet'!D14 -> 0.5 | E8: ='Data Sheet'!E16/'Data Sheet'!E14 -> 0.5 | F8: ='Data Sheet'!F16/'Data Sheet'!F14 -> 0.5 | G8: ='Data Sheet'!G16/'Data Sheet'!G14 -> 0.5 | H8: =AVERAGE(C8:G8) -> 0.5 | I8: =AVERAGE(D8:H8) -> 0.5 | J8: =AVERAGE(E8:I8) -> 0.5 | K8: =AVERAGE(F8:J8) -> 0.5 | L8: =AVERAGE(G8:K8) -> 0.5
A9: Operating Expenses SG&A (% of Revenue) | C9: ='Data Sheet'!C17/'Data Sheet'!C14 -> 0.25278557 | D9: ='Data Sheet'!D17/'Data Sheet'!D14 -> 0.25485261 | E9: ='Data Sheet'!E17/'Data Sheet'!E14 -> 0.26645758 | F9: ='Data Sheet'!F17/'Data Sheet'!F14 -> 0.26310262 | G9: ='Data Sheet'!G17/'Data Sheet'!G14 -> 0.28707931 | H9: 0.26 | I9: 0.26 | J9: 0.26 | K9: 0.26 | L9: 0.26
A10: Depreciation & Amortization (% of PPE) | C10: =-'Calculation Sheet'!C7/'Calculation Sheet'!C5 -> 0.02148 | D10: =-'Calculation Sheet'!D7/'Calculation Sheet'!D5 -> 0.021207939 | E10: =-'Calculation Sheet'!E7/'Calculation Sheet'!E5 -> 0.022089251 | F10: =-'Calculation Sheet'!F7/'Calculation Sheet'!F5 -> 0.02308364 | G10: =-'Calculation Sheet'!G7/'Calculation Sheet'!G5 -> 0.025212117 | H10: 0.025 | I10: 0.025 | J10: 0.025 | K10: 0.025 | L10: 0.025
A11: Other Income (% of Rev) | C11: ='Data Sheet'!C20/'Data Sheet'!C14 -> 0.0036361317 | D11: ='Data Sheet'!D20/'Data Sheet'!D14 -> 0.0040803874 | E11: ='Data Sheet'!E20/'Data Sheet'!E14 -> 0.0073786728 | F11: ='Data Sheet'!F20/'Data Sheet'!F14 -> 0.013134936 | G11: ='Data Sheet'!G20/'Data Sheet'!G14 -> 0.021425776 | H11: 0.015 | I11: 0.015 | J11: 0.015 | K11: 0.015 | L11: 0.015
A12: Interest(%of rev) | C12: ='Data Sheet'!C22/'Data Sheet'!C14 -> 0.0024878796 | D12: ='Data Sheet'!D22/'Data Sheet'!D14 -> 0.0020211265 | E12: ='Data Sheet'!E22/'Data Sheet'!E14 -> 0.0018818092 | F12: ='Data Sheet'!F22/'Data Sheet'!F14 -> 0.0053961484 | G12: ='Data Sheet'!G22/'Data Sheet'!G14 -> 0.0064407775 | H12: 0.006 | I12: 0.006 | J12: 0.006 | K12: 0.006 | L12: 0.006
A13: Tax Rate (% of Earnings Before Tax) | C13: ='Data Sheet'!C24/'Data Sheet'!C23 -> 0.24570998 | D13: ='Data Sheet'!D24/'Data Sheet'!D23 -> 0.25155803 | E13: ='Data Sheet'!E24/'Data Sheet'!E23 -> 0.23988309 | F13: ='Data Sheet'!F24/'Data Sheet'!F23 -> 0.26166882 | G13: ='Data Sheet'!G24/'Data Sheet'!G23 -> 0.26002218 | H13: 0.25 | I13: 0.25 | J13: 0.25 | K13: 0.25 | L13: 0.25
A14: Accounts Receivable (Days) | C14: =('Data Sheet'!C32/'Data Sheet'!C14)*C21 -> 18.246895 | D14: =('Data Sheet'!D32/'Data Sheet'!D14)*D21 -> 18.247912 | E14: =('Data Sheet'!E32/'Data Sheet'!E14)*E21 -> 18.25 | F14: =('Data Sheet'!F32/'Data Sheet'!F14)*F21 -> 18.251179 | G14: =('Data Sheet'!G32/'Data Sheet'!G14)*G21 -> 18.247619 | H14: 18.25 | I14: 18.25 | J14: 18.25 | K14: 18.25 | L14: 18.25
A15: Inventory (Days) | C15: =('Data Sheet'!C33/'Data Sheet'!C15)*'Assumption Sheet'!C21 -> 36.493791 | D15: =('Data Sheet'!D33/'Data Sheet'!D15)*'Assumption Sheet'!D21 -> 36.495824 | E15: =('Data Sheet'!E33/'Data Sheet'!E15)*'Assumption Sheet'!E21 -> 36.5 | F15: =('Data Sheet'!F33/'Data Sheet'!F15)*'Assumption Sheet'!F21 -> 36.502359 | G15: =('Data Sheet'!G33/'Data Sheet'!G15)*'Assumption Sheet'!G21 -> 36.495239 | H15: =G15 -> 36.495239 | I15: =H15 -> 36.495239 | J15: =I15 -> 36.495239 | K15: =J15 -> 36.495239 | L15: =K15 -> 36.495239
A16: Accounts Payable/other CL days (Days) | C16: =('Data Sheet'!C43/'Data Sheet'!C15)*'Assumption Sheet'!C21 -> 73.003105 | D16: =('Data Sheet'!D43/'Data Sheet'!D15)*'Assumption Sheet'!D21 -> 73.005568 | E16: =('Data Sheet'!E43/'Data Sheet'!E15)*'Assumption Sheet'!E21 -> 73 | F16: =('Data Sheet'!F43/'Data Sheet'!F15)*'Assumption Sheet'!F21 -> 73.004718 | G16: =('Data Sheet'!G43/'Data Sheet'!G15)*'Assumption Sheet'!G21 -> 73.002381 | H16: 73 | I16: 73 | J16: 73 | K16: 73 | L16: 73
A17: Capital Expenditures (% of PPE) | C17: =-'Data Sheet'!C75/'Data Sheet'!C14 -> 0.053521306 | D17: =-'Data Sheet'!D75/'Data Sheet'!D14 -> 0.021374366 | E17: =-'Data Sheet'!E75/'Data Sheet'!E14 -> 0.038659624 | F17: =-'Data Sheet'!F75/'Data Sheet'!F14 -> 0.036868295 | G17: =-'Data Sheet'!G75/'Data Sheet'!G14 -> 0.03173102 | H17: 0.03 | I17: 0.03 | J17: 0.03 | K17: 0.03 | L17: 0.03
A18: Debt Issuance (Repayment) | C18: 0 | D18: 0 | E18: 0 | F18: 0 | G18: 0 | H18: 0 | I18: 0 | J18: 0 | K18: 0 | L18: 0
A19: Equity Issued (Repaid) ($000's) | C19: 0 | D19: 0 | E19: 0 | F19: 0 | G19: 0 | H19: 0 | I19: 0 | J19: 0 | K19: 0 | L19: 0
A20: Dividend Payout % | C20: =0 -> 0 | D20: =-'Data Sheet'!D78/'Data Sheet'!D25 -> 0.84392933 | E20: =-'Data Sheet'!E78/'Data Sheet'!E25 -> 0.87745243 | F20: =-'Data Sheet'!F78/'Data Sheet'!F25 -> 0.91110679 | G20: =-'Data Sheet'!G78/'Data Sheet'!G25 -> 0.91006424 | H20: 0.9 | I20: 0.9 | J20: 0.9 | K20: 0.9 | L20: 0.9
A21: Days in Period | C21: 365 | D21: 365 | E21: 365 | F21: 365 | G21: 365 | H21: 365 | I21: 365 | J21: 365 | K21: 365 | L21: 365
A27: Revenue Fluctuations assumption
A28: Bear Case | B28: =B29-4% -> 0.02
A29: Base Case | B29: 0.06 | C29: Base Case | D29: =IF(C29="BULL Case",B30,IF(C29="Bear Case",B28,IF(C29="Base Case",B29))) -> 0.06 | E29: (Three cases added via dropdown i.e base, bull, bear)
A30: Bull Case | B30: =B29+4% -> 0.1 | E30: Bull and Bear cases are prepared by adding 3% the expected growth rate and subtracting 3% respectively
A33: Cost Fluctuation Assumption
A34: Bear Case | B34: =B35-4% -> 0.46
A35: Base Case | B35: =50% -> 0.5 | C35: Base Case | D35: =IF(C35="Bull case",B36,IF(C35="Base Case",B35,IF(C35="Bear Case",B34))) -> 0.5 | E35: (Three cases added via dropdown i.e base, bull, bear)
A36: Bull Case | B36: =B35+4% -> 0.54 | E36: Bull and Bear cases are prepared by adding 3% the expected growth rate and subtracting 3% respectively

Sheet Data Sheet
A1: COMPANY NAME | B1: HINDUSTAN UNILEVER LTD
A2: LATEST VERSION
A3: CURRENT VERSION
A5: META
A6: Number of shares
A7: Face Value | B7: 1
A8: Current Price | B8: 1975
A9: Market Capitalization | B9: 463997.75
A12: PROFIT & LOSS
A13: Report Date | C13: 44286 | D13: 44651 | E13: 45016 | F13: 45382 | G13: 45747
A14: Revenue | C14: 47028 | D14: 52446 | E14: 60580 | F14: 61896 | G14: 61328
A15: Cost of Goods Sold | C15: 23514 | D15: 26223 | E15: 30290 | F15: 30948 | G15: 30664
A16: Gross Profit | C16: 23514 | D16: 26223 | E16: 30290 | F16: 30948 | G16: 30664
A17: Operating Expenses (SG&A) | C17: 11888 | D17: 13366 | E17: 16142 | F17: 16285 | G17: 17606
A18: (EBITDA) | C18: 11626 | D18: 12875 | E18: 14148 | F18: 14663 | G18: 13058
A19: Depreciation & Ammortization | C19: 1074 | D19: 1074 | E19: 1074 | F19: 1074 | G19: 1074
A20: Other Incomes | C20: 171 | D20: 214 | E20: 447 | F20: 813 | G20: 1314
A21: Earning Before Interest & Tax (EBIT) | C21: 10723 | D21: 12015 | E21: 13521 | F21: 14402 | G21: 13298
A22: Interest Expense | C22: 117 | D22: 106 | E22: 114 | F22: 334 | G22: 395
A23: Earning Before Tax (EBT) | C23: 10606 | D23: 11874 | E23: 13344 | F23: 13926 | G23: 12622
A24: Income Tax Expense | C24: 2606 | D24: 2987 | E24: 3201 | F24: 3644 | G24: 3282
A25: Net Income | C25: 8000 | D25: 8887 | E25: 10143 | F25: 10282 | G25: 9340
A27: BALANCE SHEET
A28: Report Date | C28: 44286 | D28: 44651 | E28: 45016 | F28: 45382 | G28: 45747
A30: Current Assets
A31: Cash | C31: 7557 | D31: 8914 | E31: 8951 | F31: 8799 | G31: 9049
A32: Accounts Receivable | C32: 2351 | D32: 2622 | E32: 3029 | F32: 3095 | G32: 3066
A33: Inventory | C33: 2351 | D33: 2622 | E33: 3029 | F33: 3095 | G33: 3066
A34: Prepaid Expenses | C34: 0 | D34: 0 | E34: 0 | F34: 0 | G34: 0
A35: Total Current Assets | C35: =SUM(C31:C34) -> 12259 | D35: =SUM(D31:D34) -> 14158 | E35: =SUM(E31:E34) -> 15009 | F35: =SUM(F31:F34) -> 14989 | G35: =SUM(G31:G34) -> 15181
A37: Fixed Assets
A38: PP&E, Net of Accum. Depreciation | C38: 51443 | D38: 51473 | E38: 52678 | F38: 53744 | G38: 54335
A40: TOTAL ASSETS | C40: =63702 -> 63702 | D40: 65631 | E40: =SUM(E35,E38) -> 67687 | F40: 68733 | G40: 69516
A42: Current Liabilities
A43: Accounts Payable | C43: 4703 | D43: 5245 | E43: 6058 | F43: 6190 | G43: 6133
A44: Line of Credit | C44: - | D44: - | E44: - | F44: - | G44: -
A45: Current Maturities of Long Term Debt | C45: - | D45: - | E45: - | F45: - | G45: -
A46: Total Current Liabilities | C46: =SUM(C43:C45) -> 4703 | D46: =SUM(D43:D45) -> 5245 | E46: =SUM(E43:E45) -> 6058 | F46: =SUM(F43:F45) -> 6190 | G46: =SUM(G43:G45) -> 6133
A48: Long Term Liabilities
A49: Long Term Debt, Net of Current Maturities | C49: 11325 | D49: 11325 | E49: 11325 | F49: 11325 | G49: 11325
...

Sheet HUL IS
A1: Integrated Financial Statements
A2: Hindustan Unilever
A3: (IN Crores)
C5: Historical | D5: Historical | E5: Historical | F5: Historical | G5: Historical | H5: Projected | I5: Projected | J5: Projected | K5: Projected | L5: Projected
A6: INCOME STATEMENT | C6: 2021 | D6: 2022 | E6: 2023 | F6: 2024 | G6: 2025 | H6: 2026 | I6: 2027 | J6: 2028 | K6: 2029 | L6: 2030
A8: Revenue | C8: ='Data Sheet'!C14 -> 47028 | D8: ='Data Sheet'!D14 -> 52446 | E8: ='Data Sheet'!E14 -> 60580 | F8: ='Data Sheet'!F14 -> 61896 | G8: ='Data Sheet'!G14 -> 61328 | H8: =G8+G8*H9 -> 65007.68 | I8: =H8+H8*I9 -> 68908.141 | J8: =I8+I8*J9 -> 73042.629 | K8: =J8+J8*K9 -> 77425.187 | L8: =K8+K8*L9 -> 82070.698
A9: Growth (%) | C9: ='Assumption Sheet'!C6 -> - | D9: ='Assumption Sheet'!D6 -> 0.11520796 | E9: ='Assumption Sheet'!E6 -> 0.15509286 | F9: ='Assumption Sheet'!F6 -> 0.021723341 | G9: ='Assumption Sheet'!G6 -> -0.0091766835 | H9: ='Assumption Sheet'!H6 -> 0.06 | I9: ='Assumption Sheet'!I6 -> 0.06 | J9: ='Assumption Sheet'!J6 -> 0.06 | ... L9: ='Assumption Sheet'!L6 -> 0.06
A11: Cost of Goods Sold | C11: =-'Data Sheet'!C15 -> -23514 | D11: =-'Data Sheet'!D15 -> -26223 | E11: =-'Data Sheet'!E15 -> -30290 | F11: =-'Data Sheet'!F15 -> -30948 | G11: =-'Data Sheet'!G15 -> -30664 | H11: =-H8*H12 -> -32503.84 | I11: =-I8*I12 -> -34454.07 | J11: =-J8*J12 -> -36521.315 | K11: =-K8*K12 -> -38712.594 | L11: =-L8*L12 -> -41035.349
A12: % of Rev. | C12: ='Assumption Sheet'!C7 -> 0.5 | D12: ='Assumption Sheet'!D7 -> 0.5 | E12: ='Assumption Sheet'!E7 -> 0.5 | F12: ='Assumption Sheet'!F7 -> 0.5 | G12: ='Assumption Sheet'!G7 -> 0.5 | H12: ='Assumption Sheet'!H7 -> 0.5 | I12: ='Assumption Sheet'!I7 -> 0.5 | J12: ='Assumption Sheet'!J7 -> 0.5 | ... L12: ='Assumption Sheet'!L7 -> 0.5
A14: Gross Profit | C14: ='Data Sheet'!C16 -> 23514 | D14: ='Data Sheet'!D16 -> 26223 | E14: ='Data Sheet'!E16 -> 30290 | F14: ='Data Sheet'!F16 -> 30948 | G14: ='Data Sheet'!G16 -> 30664 | H14: =SUM(H8,H11) -> 32503.84 | I14: =SUM(I8,I11) -> 34454.07 | J14: =SUM(J8,J11) -> 36521.315 | K14: =SUM(K8,K11) -> 38712.594 | L14: =SUM(L8,L11) -> 41035.349
A17: Operating Expenses (SG&A) | C17: =-'Data Sheet'!C17 -> -11888 | D17: =-'Data Sheet'!D17 -> -13366 | E17: =-'Data Sheet'!E17 -> -16142 | F17: =-'Data Sheet'!F17 -> -16285 | G17: =-'Data Sheet'!G17 -> -17606 | H17: =-H8*H18 -> -16901.997 | I17: =-I8*I18 -> -17916.117 | J17: =-J8*J18 -> -18991.084 | K17: =-K8*K18 -> -20130.549 | L17: =-L8*L18 -> -21338.382
A18: % of REV | C18: ='Assumption Sheet'!C9 -> 0.25278557 | D18: ='Assumption Sheet'!D9 -> 0.25485261 | E18: ='Assumption Sheet'!E9 -> 0.26645758 | F18: ='Assumption Sheet'!F9 -> 0.26310262 | G18: ='Assumption Sheet'!G9 -> 0.28707931 | H18: ='Assumption Sheet'!H9 -> 0.26 | I18: ='Assumption Sheet'!I9 -> 0.26 | J18: ='Assumption Sheet'!J9 -> 0.26 | ... L18: ='Assumption Sheet'!L9 -> 0.26 | N18: The variation of formulas and linking will only be in Hiatoricals as the Data are from trading platforms
A20: (EBITDA) | C20: ='Data Sheet'!C18 -> 11626 | D20: ='Data Sheet'!D18 -> 12875 | E20: ='Data Sheet'!E18 -> 14148 | F20: ='Data Sheet'!F18 -> 14663 | G20: ='Data Sheet'!G18 -> 13058 | H20: =SUM(H14,H17) -> 15601.843 | I20: =SUM(I14,I17) -> 16537.954 | J20: =SUM(J14,J17) -> 17530.231 | K20: =SUM(K14,K17) -> 18582.045 | L20: =SUM(L14,L17) -> 19696.968
A22: Depreciation & Ammortization | C22: =-'Data Sheet'!C19 -> -1074 | D22: =-'Data Sheet'!D19 -> -1074 | E22: =-'Data Sheet'!E19 -> -1074 | F22: =-'Data Sheet'!F19 -> -1074 | G22: =-'Data Sheet'!G19 -> -1074 | H22: ='Calculation Sheet'!H7 -> -1358.375 | I22: ='Calculation Sheet'!I7 -> -1373.1714 | J22: ='Calculation Sheet'!J7 -> -1390.5232 | K22: ='Calculation Sheet'!K7 -> -1410.5421 | L22: ='Calculation Sheet'!L7 -> -1433.3474
A23: % of PPe | C23: ='Assumption Sheet'!C10 -> 0.02148 | D23: ='Assumption Sheet'!D10 -> 0.021207939 | E23: ='Assumption Sheet'!E10 -> 0.022089251 | F23: ='Assumption Sheet'!F10 -> 0.02308364 | G23: ='Assumption Sheet'!G10 -> 0.025212117 | H23: ='Assumption Sheet'!H10 -> 0.025 | I23: ='Assumption Sheet'!I10 -> 0.025 | J23: ='Assumption Sheet'!J10 -> 0.025 | ... L23: ='Assumption Sheet'!L10 -> 0.025
A25: Other Incomes | C25: ='Data Sheet'!C20 -> 171 | D25: ='Data Sheet'!D20 -> 214 | E25: ='Data Sheet'!E20 -> 447 | F25: ='Data Sheet'!F20 -> 813 | G25: ='Data Sheet'!G20 -> 1314 | H25: =H8*H26 -> 975.1152 | I25: =I8*I26 -> 1033.6221 | J25: =J8*J26 -> 1095.6394 | K25: =K8*K26 -> 1161.3778 | L25: =L8*L26 -> 1231.0605
A26: % of REV | C26: ='Assumption Sheet'!C11 -> 0.0036361317 | D26: ='Assumption Sheet'!D11 -> 0.0040803874 | E26: ='Assumption Sheet'!E11 -> 0.0073786728 | F26: ='Assumption Sheet'!F11 -> 0.013134936 | G26: ='Assumption Sheet'!G11 -> 0.021425776 | H26: ='Assumption Sheet'!H11 -> 0.015 | I26: ='Assumption Sheet'!I11 -> 0.015 | J26: ='Assumption Sheet'!J11 -> 0.015 | ... L26: ='Assumption Sheet'!L11 -> 0.015
A28: Earning Before Interest & Tax (EBIT) | C28: ='Data Sheet'!C21 -> 10723 | D28: ='Data Sheet'!D21 -> 12015 | E28: ='Data Sheet'!E21 -> 13521 | F28: ='Data Sheet'!F21 -> 14402 | G28: ='Data Sheet'!G21 -> 13298 | H28: =SUM(H20,H22,H25) -> 15218.583 | I28: =SUM(I20,I22,I25) -> 16198.405 | J28: =SUM(J20,J22,J25) -> 17235.347 | K28: =SUM(K20,K22,K25) -> 18332.881 | L28: =SUM(L20,L22,L25) -> 19494.681
A30: Interest Expense | C30: =-'Data Sheet'!C22 -> -117 | D30: =-'Data Sheet'!D22 -> -106 | E30: =-'Data Sheet'!E22 -> -114 | F30: =-'Data Sheet'!F22 -> -334 | G30: =-'Data Sheet'!G22 -> -395 | H30: =-H8*'Assumption Sheet'!H12 -> -390.04608 | I30: =-I8*'Assumption Sheet'!I12 -> -413.44884 | J30: =-J8*'Assumption Sheet'!J12 -> -438.25578 | K30: =-K8*'Assumption Sheet'!K12 -> -464.55112 | L30: =-L8*'Assumption Sheet'!L12 -> -492.42419
A31: % of REV | C31: ='Assumption Sheet'!C12 -> 0.0024878796 | D31: ='Assumption Sheet'!D12 -> 0.0020211265 | E31: ='Assumption Sheet'!E12 -> 0.0018818092 | F31: ='Assumption Sheet'!F12 -> 0.0053961484 | G31: ='Assumption Sheet'!G12 -> 0.0064407775
A33: Earning Before Tax (EBT) | C33: ='Data Sheet'!C23 -> 10606 | D33: ='Data Sheet'!D23 -> 11874 | E33: ='Data Sheet'!E23 -> 13344 | F33: ='Data Sheet'!F23 -> 13926 | G33: ='Data Sheet'!G23 -> 12622 | H33: =SUM(H28,H30) -> 14828.537 | I33: =SUM(I28,I30) -> 15784.956 | J33: =SUM(J28,J30) -> 16797.091 | K33: =SUM(K28,K30) -> 17868.329 | L33: =SUM(L28,L30) -> 19002.256
A35: Income Tax Expense | C35: =-'Data Sheet'!C24 -> -2606 | D35: =-'Data Sheet'!D24 -> -2987 | E35: =-'Data Sheet'!E24 -> -3201 | F35: =-'Data Sheet'!F24 -> -3644 | G35: =-'Data Sheet'!G24 -> -3282 | H35: =-H33*H36 -> -3707.1343 | I35: =-I33*I36 -> -3946.2389 | J35: =-J33*J36 -> -4199.2729 | K35: =-K33*K36 -> -4467.0824 | L35: =-L33*L36 -> -4750.5641
A36: Tax Rate | C36: ='Assumption Sheet'!C13 -> 0.24570998 | D36: ='Assumption Sheet'!D13 -> 0.25155803 | E36: ='Assumption Sheet'!E13 -> 0.23988309 | F36: ='Assumption Sheet'!F13 -> 0.26166882 | G36: ='Assumption Sheet'!G13 -> 0.26002218 | H36: ='Assumption Sheet'!H13 -> 0.25 | I36: ='Assumption Sheet'!I13 -> 0.25 | J36: ='Assumption Sheet'!J13 -> 0.25 | ... L36: ='Assumption Sheet'!L13 -> 0.25
A38: Net Income | C38: ='Data Sheet'!C25 -> 8000 | D38: ='Data Sheet'!D25 -> 8887 | E38: ='Data Sheet'!E25 -> 10143 | F38: ='Data Sheet'!F25 -> 10282 | G38: ='Data Sheet'!G25 -> 9340 | H38: =SUM(H33,H35) -> 11121.403 | I38: =SUM(I33,I35) -> 11838.717 | J38: =SUM(J33,J35) -> 12597.819 | K38: =SUM(K33,K35) -> 13401.247 | L38: =SUM(L33,L35) -> 14251.692

Sheet HUL BS
C1: Historical | D1: Historical | E1: Historical | F1: Historical | G1: Historical | H1: Projected | I1: Projected | J1: Projected | K1: Projected | L1: Projected
A2: BALANCE SHEET | C2: ='HUL IS'!C6 -> 2021 | D2: ='HUL IS'!D6 -> 2022 | E2: ='HUL IS'!E6 -> 2023 | F2: ='HUL IS'!F6 -> 2024 | G2: ='HUL IS'!G6 -> 2025 | H2: ='HUL IS'!H6 -> 2026 | I2: ='HUL IS'!I6 -> 2027 | J2: ='HUL IS'!J6 -> 2028 | ... L2: ='HUL IS'!L6 -> 2030
A4: Current Assets
A5: Cash | C5: ='Data Sheet'!C31 -> 7557 | D5: ='Data Sheet'!D31 -> 8914 | E5: ='Data Sheet'!E31 -> 8951 | F5: ='Data Sheet'!F31 -> 8799 | G5: ='Data Sheet'!G31 -> 9049 | H5: ='HUL CS'!H28 -> 9568.7089 | I5: ='HUL CS'!I28 -> 10058.533 | J5: ='HUL CS'!J28 -> 10517.586 | K5: ='HUL CS'!K28 -> 10945.526 | L5: ='HUL CS'!L28 -> 11341.952
A6: Accounts Receivable | C6: ='Data Sheet'!C32 -> 2351 | D6: ='Data Sheet'!D32 -> 2622 | E6: ='Data Sheet'!E32 -> 3029 | F6: ='Data Sheet'!F32 -> 3095 | G6: ='Data Sheet'!G32 -> 3066 | H6: =('HUL IS'!H8/'Assumption Sheet'!H21)*'Assumption Sheet'!H14 -> 3250.384 | I6: =('HUL IS'!I8/'Assumption Sheet'!I21)*'Assumption Sheet'!I14 -> 3445.407 | J6: =('HUL IS'!J8/'Assumption Sheet'!J21)*'Assumption Sheet'!J14 -> 3652.1315 | K6: =('HUL IS'!K8/'Assumption Sheet'!K21)*'Assumption Sheet'!K14 -> 3871.2594 | L6: =('HUL IS'!L8/'Assumption Sheet'!L21)*'Assumption Sheet'!L14 -> 4103.5349
A7: Inventory | C7: ='Data Sheet'!C33 -> 2351 | D7: ='Data Sheet'!D33 -> 2622 | E7: ='Data Sheet'!E33 -> 3029 | F7: ='Data Sheet'!F33 -> 3095 | G7: ='Data Sheet'!G33 -> 3066 | H7: =-('HUL IS'!H11/'Assumption Sheet'!H21)*'Assumption Sheet'!H15 -> 3249.96 | I7: =-('HUL IS'!I11/'Assumption Sheet'!I21)*'Assumption Sheet'!I15 -> 3444.9576 | J7: =-('HUL IS'!J11/'Assumption Sheet'!J21)*'Assumption Sheet'!J15 -> 3651.6551 | K7: =-('HUL IS'!K11/'Assumption Sheet'!K21)*'Assumption Sheet'!K15 -> 3870.7544 | L7: =-('HUL IS'!L11/'Assumption Sheet'!L21)*'Assumption Sheet'!L15 -> 4102.9996
A8: Prepaid Expenses | C8: ='Data Sheet'!C34 -> 0 | D8: ='Data Sheet'!D34 -> 0 | E8: ='Data Sheet'!E34 -> 0 | F8: ='Data Sheet'!F34 -> 0 | G8: ='Data Sheet'!G34 -> 0 | H8: 0 | I8: 0 | J8: 0 | K8: 0 | L8: 0
A9: Total Current Assets | C9: ='Data Sheet'!C35 -> 12259 | D9: ='Data Sheet'!D35 -> 14158 | E9: ='Data Sheet'!E35 -> 15009 | F9: ='Data Sheet'!F35 -> 14989 | G9: ='Data Sheet'!G35 -> 15181 | H9: =SUM(H5:H8) -> 16069.053 | I9: =SUM(I5:I8) -> 16948.898 | J9: =SUM(J5:J8) -> 17821.373 | K9: =SUM(K5:K8) -> 18687.54 | L9: =SUM(L5:L8) -> 19548.487
A11: Fixed Assets
A12: PP&E, Net of Accum. Depreciation | C12: ='Data Sheet'!C38 -> 51443 | D12: ='Data Sheet'!D38 -> 51473 | E12: ='Data Sheet'!E38 -> 52678 | F12: ='Data Sheet'!F38 -> 53744 | G12: ='Data Sheet'!G38 -> 54335 | H12: ='Calculation Sheet'!H8 -> 54926.855 | I12: ='Calculation Sheet'!I8 -> 55620.928 | J12: ='Calculation Sheet'!J8 -> 56421.684 | K12: ='Calculation Sheet'!K8 -> 57333.897 | L12: ='Calculation Sheet'!L8 -> 58362.671
A14: TOTAL ASSETS | C14: ='Data Sheet'!C40 -> 63702 | D14: ='Data Sheet'!D40 -> 65631 | E14: ='Data Sheet'!E40 -> 67687 | F14: ='Data Sheet'!F40 -> 68733 | G14: ='Data Sheet'!G40 -> 69516 | H14: =SUM(H9:H12) -> 70995.908 | I14: =SUM(I9:I12) -> 72569.826 | J14: =SUM(J9:J12) -> 74243.057 | K14: =SUM(K9:K12) -> 76021.437 | L14: =SUM(L9:L12) -> 77911.158
A16: Current Liabilities
A17: Accounts Payable | C17: ='Data Sheet'!C43 -> 4703 | D17: ='Data Sheet'!D43 -> 5245 | E17: ='Data Sheet'!E43 -> 6058 | F17: ='Data Sheet'!F43 -> 6190 | G17: ='Data Sheet'!G43 -> 6133 | H17: =-('HUL IS'!H11/'Assumption Sheet'!H21)*'Assumption Sheet'!H16 -> 6500.768 | I17: =-('HUL IS'!I11/'Assumption Sheet'!I21)*'Assumption Sheet'!I16 -> 6890.8141 | J17: =-('HUL IS'!J11/'Assumption Sheet'!J21)*'Assumption Sheet'!J16 -> 7304.2629 | K17: =-('HUL IS'!K11/'Assumption Sheet'!K21)*'Assumption Sheet'!K16 -> 7742.5187 | L17: =-('HUL IS'!L11/'Assumption Sheet'!L21)*'Assumption Sheet'!L16 -> 8207.0698
A18: Line of Credit | C18: ='Data Sheet'!C44 -> - | D18: ='Data Sheet'!D44 -> - | E18: ='Data Sheet'!E44 -> - | F18: ='Data Sheet'!F44 -> - | G18: ='Data Sheet'!G44 -> - | H18: - | I18: - | J18: - | K18: - | L18: -
A19: Current Maturities of Long Term Debt | C19: ='Data Sheet'!C45 -> - | D19: ='Data Sheet'!D45 -> - | E19: ='Data Sheet'!E45 -> - | F19: ='Data Sheet'!F45 -> - | G19: ='Data Sheet'!G45 -> - | H19: - | I19: - | J19: - | K19: - | L19: -
A20: Total Current Liabilities | C20: ='Data Sheet'!C46 -> 4703 | D20: ='Data Sheet'!D46 -> 5245 | E20: ='Data Sheet'!E46 -> 6058 | F20: ='Data Sheet'!F46 -> 6190 | G20: ='Data Sheet'!G46 -> 6133 | H20: =SUM(H17:H19) -> 6500.768 | I20: =SUM(I17:I19) -> 6890.8141 | J20: =SUM(J17:J19) -> 7304.2629 | K20: =SUM(K17:K19) -> 7742.5187 | L20: =SUM(L17:L19) -> 8207.0698
A22: Long Term Liabilities
A23: Long Term Debt, Net of Current Maturities | C23: ='Data Sheet'!C49 -> 11325 | D23: ='Data Sheet'!D49 -> 11325 | E23: ='Data Sheet'!E49 -> 11325 | F23: ='Data Sheet'!F49 -> 11325 | G23: ='Data Sheet'!G49 -> 11325 | H23: 11325 | I23: 11325 | J23: 11325 | K23: 11325 | L23: 11325
A25: TOTAL LIABILITIES | C25: ='Data Sheet'!C51 -> 16028 | D25: ='Data Sheet'!D51 -> 16570 | E25: ='Data Sheet'!E51 -> 17383 | F25: ='Data Sheet'!F51 -> 17515 | G25: ='Data Sheet'!G51 -> 17458 | H25: =SUM(H20:H23) -> 17825.768 | I25: =SUM(I20:I23) -> 18215.814 | J25: =SUM(J20:J23) -> 18629.263 | K25: =SUM(K20:K23) -> 19067.519 | L25: =SUM(L20:L23) -> 19532.07
A27: Common Stock | C27: ='Data Sheet'!C53 -> 235 | D27: ='Data Sheet'!D53 -> 235 | E27: ='Data Sheet'!E53 -> 235 | F27: ='Data Sheet'!F53 -> 235 | G27: ='Data Sheet'!G53 -> 235 | H27: 235 | I27: 235 | J27: 235 | K27: 235 | L27: 235
A28: Additional Paid In Capital | C28: ='Data Sheet'!C54 -> - | D28: ='Data Sheet'!D54 -> - | E28: ='Data Sheet'!E54 -> - | F28: ='Data Sheet'!F54 -> - | G28: ='Data Sheet'!G54 -> - | H28: - | I28: - | J28: - | K28: - | L28: -
A29: Retained Earnings | C29: ='Data Sheet'!C55 -> 47439 | D29: ='Data Sheet'!D55 -> 48826 | E29: ='Data Sheet'!E55 -> 50069 | F29: ='Data Sheet'!F55 -> 50983 | G29: ='Data Sheet'!G55 -> 51823 | H29: ='Calculation Sheet'!H19 -> 52935.14 | I29: ='Calculation Sheet'!I19 -> 54119.012 | J29: ='Calculation Sheet'!J19 -> 55378.794 | K29: ='Calculation Sheet'!K19 -> 56718.919 | L29: ='Calculation Sheet'!L19 -> 58144.088
A30: TOTAL EQUITY | C30: ='Data Sheet'!C56 -> 47674 | D30: ='Data Sheet'!D56 -> 49061 | E30: ='Data Sheet'!E56 -> 50304 | F30: ='Data Sheet'!F56 -> 51218 | G30: ='Data Sheet'!G56 -> 52058 | H30: =SUM(H27:H29) -> 53170.14 | I30: =SUM(I27:I29) -> 54354.012 | J30: =SUM(J27:J29) -> 55613.794 | K30: =SUM(K27:K29) -> 56953.919 | L30: =SUM(L27:L29) -> 58379.088
A32: TOTAL LIABILITIES & EQUITY | C32: =C25+C30 -> 63702 | D32: =D25+D30 -> 65631 | E32: =E25+E30 -> 67687 | F32: =F25+F30 -> 68733 | G32: =G25+G30 -> 69516 | H32: =SUM(H25,H30) -> 70995.908 | I32: =SUM(I25,I30) -> 72569.826 | J32: =SUM(J25,J30) -> 74243.057 | K32: =SUM(K25,K30) -> 76021.437 | L32: =SUM(L25,L30) -> 77911.158
A33: Check | C33: =IF(C32=C14,"OK") -> OK | D33: =IF(D32=D14,"OK") -> OK | E33: =IF(E32=E14,"OK") -> OK | F33: =IF(F32=F14,"OK") -> OK | G33: =IF(G32=G14,"OK") -> OK | H33: =IF(H32=H14,"OK") -> OK | I33: =IF(I32=I14,"OK") -> OK | J33: =IF(J32=J14,"OK") -> OK | ... L33: =IF(L32=L14,"OK") -> OK

Sheet HUL CS
C1: Historical | D1: Historical | E1: Historical | F1: Historical | G1: Historical | H1: Projected | I1: Projected | J1: Projected | K1: Projected | L1: Projected
A2: CASH FLOW STATEMENT | C2: ='HUL IS'!C6 -> 2021 | D2: ='HUL IS'!D6 -> 2022 | E2: ='HUL IS'!E6 -> 2023 | F2: ='HUL IS'!F6 -> 2024 | G2: ='HUL IS'!G6 -> 2025 | H2: ='HUL IS'!H6 -> 2026 | I2: ='HUL IS'!I6 -> 2027 | J2: ='HUL IS'!J6 -> 2028 | ... L2: ='HUL IS'!L6 -> 2030
A4: CASH FLOW FROM OPERATING ACTIVITIES
A5: Net Income | C5: ='Data Sheet'!C66 -> 8000 | D5: ='Data Sheet'!D66 -> 8887 | E5: ='Data Sheet'!E66 -> 10143 | F5: ='Data Sheet'!F66 -> 10282 | G5: ='Data Sheet'!G66 -> 9340 | H5: ='HUL IS'!H38 -> 11121.403 | I5: ='HUL IS'!I38 -> 11838.717 | J5: ='HUL IS'!J38 -> 12597.819 | K5: ='HUL IS'!K38 -> 13401.247 | L5: ='HUL IS'!L38 -> 14251.692
A7: Add Back Non-Cash Items
A8: Depreciation & Amortization | C8: ='Data Sheet'!C68 -> 1074 | D8: ='Data Sheet'!D68 -> 1074 | E8: ='Data Sheet'!E68 -> 1074 | F8: ='Data Sheet'!F68 -> 1074 | G8: ='Data Sheet'!G68 -> 1074 | H8: =-'Calculation Sheet'!H7 -> 1358.375 | I8: =-'Calculation Sheet'!I7 -> 1373.1714 | J8: =-'Calculation Sheet'!J7 -> 1390.5232 | K8: =-'Calculation Sheet'!K7 -> 1410.5421 | L8: =-'Calculation Sheet'!L7 -> 1433.3474
A10: Changes in Working Capital
A11: Accounts Receivable | C11: ='Data Sheet'!C70 -> - | D11: ='Data Sheet'!D70 -> -271 | E11: ='Data Sheet'!E70 -> -407 | F11: ='Data Sheet'!F70 -> -66 | G11: ='Data Sheet'!G70 -> 29 | H11: =-('HUL BS'!H6-'HUL BS'!G6) -> -184.384 | I11: =-('HUL BS'!I6-'HUL BS'!H6) -> -195.02304 | J11: =-('HUL BS'!J6-'HUL BS'!I6) -> -206.72442 | K11: =-('HUL BS'!K6-'HUL BS'!J6) -> -219.12789 | L11: =-('HUL BS'!L6-'HUL BS'!K6) -> -232.27556
A12: Inventory | C12: ='Data Sheet'!C71 -> - | D12: ='Data Sheet'!D71 -> -271 | E12: ='Data Sheet'!E71 -> -407 | F12: ='Data Sheet'!F71 -> -66 | G12: ='Data Sheet'!G71 -> 29 | H12: =-('HUL BS'!H7-'HUL BS'!G7) -> -183.96 | I12: =-('HUL BS'!I7-'HUL BS'!H7) -> -194.9976 | J12: =-('HUL BS'!J7-'HUL BS'!I7) -> -206.69746 | K12: =-('HUL BS'!K7-'HUL BS'!J7) -> -219.0993 | L12: =-('HUL BS'!L7-'HUL BS'!K7) -> -232.24526
A13: Accounts Payable | C13: ='Data Sheet'!C72 -> - | D13: ='Data Sheet'!D72 -> 542 | E13: ='Data Sheet'!E72 -> 813 | F13: ='Data Sheet'!F72 -> 132 | G13: ='Data Sheet'!G72 -> -57 | H13: ='HUL BS'!H17-'HUL BS'!G17 -> 367.768 | I13: ='HUL BS'!I17-'HUL BS'!H17 -> 390.04608 | J13: ='HUL BS'!J17-'HUL BS'!I17 -> 413.44884 | K13: ='HUL BS'!K17-'HUL BS'!J17 -> 438.25578 | L13: ='HUL BS'!L17-'HUL BS'!K17 -> 464.55112
A15: Net Cash Provided by Operating Activities | C15: =SUM(C5:C13) -> 9074 | D15: =SUM(D5:D13) -> 9961 | E15: =SUM(E5:E13) -> 11216 | F15: =SUM(F5:F13) -> 11356 | G15: =SUM(G5:G13) -> 10415 | H15: =SUM(H5:H13) -> 12479.202 | I15: =SUM(I5:I13) -> 13211.914 | J15: =SUM(J5:J13) -> 13988.369 | ... L15: =SUM(L5:L13) -> 15685.07
A17: CASH FLOW FROM INVESTING ACTIVITIES
A18: Capital Expenditures - Purchase of PP&E | C18: ='Data Sheet'!C75 -> -2517 | D18: ='Data Sheet'!D75 -> -1121 | E18: ='Data Sheet'!E75 -> -2342 | F18: ='Data Sheet'!F75 -> -2282 | G18: ='Data Sheet'!G75 -> -1946 | H18: =-'Calculation Sheet'!H6 -> -1950.2304 | I18: =-'Calculation Sheet'!I6 -> -2067.2442 | J18: =-'Calculation Sheet'!J6 -> -2191.2789 | K18: =-'Calculation Sheet'!K6 -> -2322.7556 | L18: =-'Calculation Sheet'!L6 -> -2462.1209
A19: Net Cash Used in Investing Activities | C19: ='Data Sheet'!C76 -> -2517 | D19: ='Data Sheet'!D76 -> -1121 | E19: ='Data Sheet'!E76 -> -2342 | F19: ='Data Sheet'!F76 -> -2282 | G19: ='Data Sheet'!G76 -> -1946 | H19: =H18 -> -1950.2304 | I19: =I18 -> -2067.2442 | J19: =J18 -> -2191.2789 | K19: =K18 -> -2322.7556 | L19: =L18 -> -2462.1209
A21: CASH FLOW FROM FINANCING ACTIVITIES
A22: Dividend paid | C22: ='Data Sheet'!C78 -> - | D22: ='Data Sheet'!D78 -> -7500 | E22: ='Data Sheet'!E78 -> -8900 | F22: ='Data Sheet'!F78 -> -9368 | G22: ='Data Sheet'!G78 -> -8500 | H22: ='Calculation Sheet'!H18 -> -10009.263 | I22: ='Calculation Sheet'!I18 -> -10654.845 | J22: ='Calculation Sheet'!J18 -> -11338.037 | K22: ='Calculation Sheet'!K18 -> -12061.122 | L22: ='Calculation Sheet'!L18 -> -12826.523
A23: Long Term Debt | C23: ='Data Sheet'!C79 -> - | D23: ='Data Sheet'!D79 -> - | E23: ='Data Sheet'!E79 -> - | F23: ='Data Sheet'!F79 -> - | G23: ='Data Sheet'!G79 -> - | H23: - | I23: - | J23: - | K23: - | L23: -
A24: Net Cash Provided by (Used in) Fnce Activities | C24: =SUM(C22:C23) -> 0 | D24: =SUM(D22:D23) -> -7500 | E24: =SUM(E22:E23) -> -8900 | F24: =SUM(F22:F23) -> -9368 | G24: =SUM(G22:G23) -> -8500 | H24: =SUM(H22:H23) -> -10009.263 | I24: =SUM(I22:I23) -> -10654.845 | J24: =SUM(J22:J23) -> -11338.037 | ... L24: =SUM(L22:L23) -> -12826.523
A26: Net Cash Flow | C26: ='Data Sheet'!C81 -> 6557 | D26: ='Data Sheet'!D81 -> 1357 | E26: ='Data Sheet'!E81 -> 37 | F26: ='Data Sheet'!F81 -> -152 | G26: ='Data Sheet'!G81 -> 250 | H26: =SUM(H15,H19,H24) -> 519.7089 | I26: =SUM(I15,I19,I24) -> 489.82428 | J26: =SUM(J15,J19,J24) -> 459.05316 | K26: =SUM(K15,K19,K24) -> 427.93978 | L26: =SUM(L15,L19,L24) -> 396.42602
A27: Beginning Cash Balance | C27: ='Data Sheet'!C82 -> 1000 | D27: =C28 -> 7557 | E27: =D28 -> 8914 | F27: =E28 -> 8951 | G27: =F28 -> 8799 | H27: =G28 -> 9049 | I27: =H28 -> 9568.7089 | J27: =I28 -> 10058.533 | K27: =J28 -> 10517.586 | L27: =K28 -> 10945.526
A28: Ending Cash Balance | C28: ='Data Sheet'!C83 -> 7557 | D28: ='Data Sheet'!D83 -> 8914 | E28: ='Data Sheet'!E83 -> 8951 | F28: ='Data Sheet'!F83 -> 8799 | G28: ='Data Sheet'!G83 -> 9049 | H28: =SUM(H26:H27) -> 9568.7089 | I28: =SUM(I26:I27) -> 10058.533 | J28: =SUM(J26:J27) -> 10517.586 | K28: =SUM(K26:K27) -> 10945.526 | L28: =SUM(L26:L27) -> 11341.952

Sheet DCF Analysis
A1: DCF Valuation Data – Hindustan Unilever
A2: Discounted Cash Flow Full (data in Rs. Crores) | K2: Sensitivity Analysis
A4: Assumptions pt1 | D4: Assumptions pt2 | M4: Growth Rates
A5: Growth rate | B5: 0.05 | D5: Beta | E5: 0.44 | K5: Implied SharePrice | L5: =C49 -> 1733.5454 | M5: 0.03 | N5: 0.04 | O5: 0.05 | P5: 0.06
A6: EV/EBITDA Multiple(In times) | B6: 35.71 | D6: Market Return | E6: 0.12 | K6: WACC | L6: 0.07 | M6: 1798.9282 | N6: 1982.7842 | O6: 2350.4961 | P6: 3453.6318
A7: Cost of Debt | B7: 0.0344 | D7: Equity value | E7: ='Data Sheet'!B9 -> 463997.75 | L7: 0.08 | M7: 1619.203 | N7: 1725.4873 | O7: 1902.6278 | P7: 2256.9087
A8: Tax Rate | B8: ='Assumption Sheet'!H13 -> 0.25 | D8: Debt value | E8: ='HUL BS'!G23 -> 11325 | L8: 0.0891 | M8: 1495.8204 | N8: 1566.6564 | O8: 1673.7256 | P8: 1854.382
A9: 10y Treasury | B9: 0.0625 | D9: Enterprise Value | E9: =E7+E8-'HUL BS'!G5 -> 466273.75 | L9: 0.1 | M9: 1377.9164 | N9: 1424.9463 | O9: 1490.7882 | P9: 1589.551
A11: Step 1 | D11: 2026 | E11: 2027 | F11: 2028 | G11: 2029 | H11: 2030
B12: Period | C12: 0 | D12: 1 | E12: 2 | F12: 3 | G12: 4 | H12: 5 | K12: Scenario Analysis
K13: Growth Rate
B14: Free Cash Flows | K14: Bear Case | L14: 0.03 | N14: Dropdowns for both is created in the assumptions part respectiverly
B15: EBIT | D15: ='HUL IS'!H28 -> 15218.583 | E15: ='HUL IS'!I28 -> 16198.405 | F15: ='HUL IS'!J28 -> 17235.347 | G15: ='HUL IS'!K28 -> 18332.881 | H15: ='HUL IS'!L28 -> 19494.681 | J15: Original | K15: Base Case | L15: 0.05
B16: Tax | D16: =-D15*$B$8 -> -3804.6458 | E16: =-E15*$B$8 -> -4049.6011 | F16: =-F15*$B$8 -> -4308.8368 | G16: =-G15*$B$8 -> -4583.2201 | H16: =-H15*$B$8 -> -4873.6702 | K16: Bull Case | L16: 0.06
B17: D&A | D17: =-'HUL IS'!H22 -> 1358.375 | E17: =-'HUL IS'!I22 -> 1373.1714 | F17: =-'HUL IS'!J22 -> 1390.5232 | G17: =-'HUL IS'!K22 -> 1410.5421 | H17: =-'HUL IS'!L22 -> 1433.3474
B18: CapEx | D18: ='HUL CS'!H18 -> -1950.2304 | E18: ='HUL CS'!I18 -> -2067.2442 | F18: ='HUL CS'!J18 -> -2191.2789 | G18: ='HUL CS'!K18 -> -2322.7556 | H18: ='HUL CS'!L18 -> -2462.1209 | K18: EV/EBITDA Multiple
B19: Non-cash Work. Capital (inc) / dec | D19: =SUM('HUL CS'!H11:H13) -> -0.576 | E19: =SUM('HUL CS'!I11:I13) -> 0.02544 | F19: =SUM('HUL CS'!J11:J13) -> 0.0269664 | G19: =SUM('HUL CS'!K11:K13) -> 0.028584384 | H19: =SUM('HUL CS'!L11:L13) -> 0.030299447 | K19: Bear Case | L19: 29
B20: FCF | D20: =SUM(D15:D19) -> 10821.506 | E20: =SUM(E15:E19) -> 11454.756 | F20: =SUM(F15:F19) -> 12125.782 | G20: =SUM(G15:G19) -> 12837.476 | H20: =SUM(H15:H19) -> 13592.267 | J20: Original | K20: Base Case | L20: 35.71
K21: Bull Case | L21: 40
A22: Step 2 | B22: WACC
B23: Cost of Equity | C23: =B9+E5*(E6-B9) -> 0.0878 | E23: (CAPM Formula)
B24: D/D+E | C24: =E8/(E7+E8) -> 0.023825916
B25: E/D+E | C25: =E7/(E7+E8) -> 0.97617408
B26: WACC | C26: =(C25*C23)+(C24*B7)*(1-B8) -> 0.086322793 | E26: (Apply WACC Formula)
A28: Step 3 | B28: Terminal Value
B29: EBITDA | H29: ='HUL IS'!L20 -> 19696.968
B30: Terminal Value (Exit Multiple) | H30: =H29*B6 -> 703378.71
B31: Perpetuity Growth | H31: =(H20*(1+B5)/(C26-B5)) -> 392918.04
B32: Average | H32: =AVERAGE(H30:H31) -> 548148.37
A34: Step 4 | B34: Discounting | C34: =C12 -> 0 | D34: =D12 -> 1 | E34: =E12 -> 2 | F34: =F12 -> 3 | G34: =G12 -> 4 | H34: =H12 -> 5
B35: Discount Factor | D35: =1/(1+$C$26)^D34 -> 0.9205367 | E35: =1/(1+$C$26)^E34 -> 0.84738782 | F35: =1/(1+$C$26)^F34 -> 0.78005159 | G35: =1/(1+$C$26)^G34 -> 0.71806611 | H35: =1/(1+$C$26)^H34 -> 0.66100621
B36: PV of FCF | D36: =D20*D35 -> 9961.5936 | E36: =E20*E35 -> 9706.6207 | F36: =F20*F35 -> 9458.7353 | G36: =G20*G35 -> 9218.1561 | H36: =H20*H35 -> 8984.5731
B37: PV of TV | H37: =H32*H35 -> 362329.48
B38: Enterprise Value | C38: =SUM(D36:H37) -> 409659.16
A41: Step 5 | B41: Enterprise Value to Equity Value
B42: Cash | C42: ='HUL BS'!G5 -> 9049
B43: Marketable Securities | C43: 0
B44: Short term Debt | C44: 0
B45: Long term Debt | C45: ='HUL BS'!G23 -> 11325
B46: Equity Value | C46: =C38+C42+C43-C44-C45 -> 407383.16
...

Sheet Ratio Analysis
A1: Ratio Analysis | C1: Historical | D1: Historical | E1: Historical | F1: Historical | G1: Historical | H1: Projected | I1: Projected | J1: Projected | K1: Projected | L1: Projected
C2: 2021 | D2: 2022 | E2: 2023 | F2: 2024 | G2: 2025 | H2: 2026 | I2: 2027 | J2: 2028 | K2: 2029 | L2: 2030
A3: liquidity Ratios
A4: Current Ratio | C4: ='HUL BS'!C9/'HUL BS'!C20 -> 2.6066341 | D4: ='HUL BS'!D9/'HUL BS'!D20 -> 2.6993327 | E4: ='HUL BS'!E9/'HUL BS'!E20 -> 2.4775503 | F4: ='HUL BS'!F9/'HUL BS'!F20 -> 2.4214863 | G4: ='HUL BS'!G9/'HUL BS'!G20 -> 2.4752976 | H4: ='HUL BS'!H9/'HUL BS'!H20 -> 2.4718699 | I4: ='HUL BS'!I9/'HUL BS'!I20 -> 2.4596365 | J4: ='HUL BS'!J9/'HUL BS'!J20 -> 2.4398592 | ... L4: ='HUL BS'!L9/'HUL BS'!L20 -> 2.3819082
A5: Quick Ratio | C5: =('HUL BS'!C5+'HUL BS'!C6)/'HUL BS'!C20 -> 2.1067404 | D5: =('HUL BS'!D5+'HUL BS'!D6)/'HUL BS'!D20 -> 2.199428 | E5: =('HUL BS'!E5+'HUL BS'!E6)/'HUL BS'!E20 -> 1.9775503 | F5: =('HUL BS'!F5+'HUL BS'!F6)/'HUL BS'!F20 -> 1.9214863 | G5: =('HUL BS'!G5+'HUL BS'!G6)/'HUL BS'!G20 -> 1.9753791 | H5: =('HUL BS'!H5+'HUL BS'!H6)/'HUL BS'!H20 -> 1.9719351 | I5: =('HUL BS'!I5+'HUL BS'!I6)/'HUL BS'!I20 -> 1.9597017 | J5: =('HUL BS'!J5+'HUL BS'!J6)/'HUL BS'!J20 -> 1.9399244 | ... L5: =('HUL BS'!L5+'HUL BS'!L6)/'HUL BS'!L20 -> 1.8819734
A7: Profitability Ratios
A8: Net Profit Ratio | C8: ='HUL IS'!C38/'HUL IS'!C8 -> 0.17011142 | D8: ='HUL IS'!D38/'HUL IS'!D8 -> 0.16945048 | E8: ='HUL IS'!E38/'HUL IS'!E8 -> 0.1674315 | F8: ='HUL IS'!F38/'HUL IS'!F8 -> 0.16611736 | G8: ='HUL IS'!G38/'HUL IS'!G8 -> 0.15229585 | H8: ='HUL IS'!H38/'HUL IS'!H8 -> 0.17107829 | I8: ='HUL IS'!I38/'HUL IS'!I8 -> 0.17180433 | J8: ='HUL IS'!J38/'HUL IS'!J8 -> 0.17247214 | ... L8: ='HUL IS'!L38/'HUL IS'!L8 -> 0.17365141
A9: Gross Profit Ratio | C9: ='HUL IS'!C14/'HUL IS'!C8 -> 0.5 | D9: ='HUL IS'!D14/'HUL IS'!D8 -> 0.5 | E9: ='HUL IS'!E14/'HUL IS'!E8 -> 0.5 | F9: ='HUL IS'!F14/'HUL IS'!F8 -> 0.5 | G9: ='HUL IS'!G14/'HUL IS'!G8 -> 0.5 | H9: ='HUL IS'!H14/'HUL IS'!H8 -> 0.5 | I9: ='HUL IS'!I14/'HUL IS'!I8 -> 0.5 | J9: ='HUL IS'!J14/'HUL IS'!J8 -> 0.5 | ... L9: ='HUL IS'!L14/'HUL IS'!L8 -> 0.5
A10: Operating profit Ratio | C10: ='HUL IS'!C20/'HUL IS'!C8 -> 0.24721443 | D10: ='HUL IS'!D20/'HUL IS'!D8 -> 0.2454906 | E10: ='HUL IS'!E20/'HUL IS'!E8 -> 0.23354242 | F10: ='HUL IS'!F20/'HUL IS'!F8 -> 0.23689738 | G10: ='HUL IS'!G20/'HUL IS'!G8 -> 0.21292069 | H10: ='HUL IS'!H20/'HUL IS'!H8 -> 0.24 | I10: ='HUL IS'!I20/'HUL IS'!I8 -> 0.24 | J10: ='HUL IS'!J20/'HUL IS'!J8 -> 0.24 | ... L10: ='HUL IS'!L20/'HUL IS'!L8 -> 0.24
A11: ROCE | C11: ='HUL IS'!C28/('HUL BS'!C14-'HUL BS'!C20) -> 0.18174884 | D11: ='HUL IS'!D28/('HUL BS'!D14-'HUL BS'!D20) -> 0.19896996 | E11: ='HUL IS'!E28/('HUL BS'!E14-'HUL BS'!E20) -> 0.21939347 | F11: ='HUL IS'!F28/('HUL BS'!F14-'HUL BS'!F20) -> 0.23027357 | G11: ='HUL IS'!G28/('HUL BS'!G14-'HUL BS'!G20) -> 0.20980389 | H11: ='HUL IS'!H28/('HUL BS'!H14-'HUL BS'!H20) -> 0.23596481 | I11: ='HUL IS'!I28/('HUL BS'!I14-'HUL BS'!I20) -> 0.24662984 | J11: ='HUL IS'!J28/('HUL BS'!J14-'HUL BS'!J20) -> 0.2574792 | ... L11: ='HUL IS'!L28/('HUL BS'!L14-'HUL BS'!L20) -> 0.27967772
A13: Solvency Ratios
A14: Debt Equity Ratio | C14: ='HUL BS'!C23/('HUL BS'!C14-'HUL BS'!C25) -> 0.23755087 | D14: ='HUL BS'!D23/('HUL BS'!D14-'HUL BS'!D25) -> 0.23083508 | E14: ='HUL BS'!E23/('HUL BS'!E14-'HUL BS'!E25) -> 0.2251312 | F14: ='HUL BS'!F23/('HUL BS'!F14-'HUL BS'!F25) -> 0.22111367 | G14: ='HUL BS'!G23/('HUL BS'!G14-'HUL BS'!G25) -> 0.21754581 | H14: ='HUL BS'!H23/('HUL BS'!H14-'HUL BS'!H25) -> 0.21299549 | I14: ='HUL BS'!I23/('HUL BS'!I14-'HUL BS'!I25) -> 0.20835628 | J14: ='HUL BS'!J23/('HUL BS'!J14-'HUL BS'!J25) -> 0.20363653 | ... L14: ='HUL BS'!L23/('HUL BS'!L14-'HUL BS'!L25) -> 0.1939907
A15: Interest Coverage Ratio | C15: ='HUL IS'!C28/(-'HUL IS'!C30) -> 91.649573 | D15: ='HUL IS'!D28/(-'HUL IS'!D30) -> 113.34906 | E15: ='HUL IS'!E28/(-'HUL IS'!E30) -> 118.60526 | F15: ='HUL IS'!F28/(-'HUL IS'!F30) -> 43.11976 | G15: ='HUL IS'!G28/(-'HUL IS'!G30) -> 33.665823 | H15: ='HUL IS'!H28/(-'HUL IS'!H30) -> 39.017399 | I15: ='HUL IS'!I28/(-'HUL IS'!I30) -> 39.178739 | J15: ='HUL IS'!J28/(-'HUL IS'!J30) -> 39.327142 | ... L15: ='HUL IS'!L28/(-'HUL IS'!L30) -> 39.589202
A17: Turnover Ratios
A18: Inventory turnover | C18: =-'HUL IS'!C11/'HUL BS'!C7 -> 10.001701 | D18: =-'HUL IS'!D11/(('HUL BS'!D7+'HUL BS'!C7)/2) -> 10.546149 | E18: =-'HUL IS'!E11/(('HUL BS'!E7+'HUL BS'!D7)/2) -> 10.720227 | F18: =-'HUL IS'!F11/(('HUL BS'!F7+'HUL BS'!E7)/2) -> 10.10712 | G18: =-'HUL IS'!G11/(('HUL BS'!G7+'HUL BS'!F7)/2) -> 9.9542282 | H18: =-'HUL IS'!H11/(('HUL BS'!H7+'HUL BS'!G7)/2) -> 10.292605 | I18: =-'HUL IS'!I11/(('HUL BS'!I7+'HUL BS'!H7)/2) -> 10.292605 | J18: =-'HUL IS'!J11/(('HUL BS'!J7+'HUL BS'!I7)/2) -> 10.292605 | K18: =-'HUL IS'!K11/(('HUL BS'!K7+'HUL BS'!J7)/2) -> 10.292605 | L18: =-'HUL IS'!L11/(('HUL BS'!L7+'HUL BS'!K7)/2) -> 10.292605
A19: Debtor turnover | C19: ='HUL IS'!C8/('HUL BS'!C6) -> 20.003403 | D19: ='HUL IS'!D8/(('HUL BS'!D6+'HUL BS'!C6)/2) -> 21.092298 | E19: ='HUL IS'!E8/(('HUL BS'!E6+'HUL BS'!D6)/2) -> 21.440453 | F19: ='HUL IS'!F8/(('HUL BS'!F6+'HUL BS'!E6)/2) -> 20.214239 | G19: ='HUL IS'!G8/(('HUL BS'!G6+'HUL BS'!F6)/2) -> 19.908456 | H19: ='HUL IS'!H8/(('HUL BS'!H6+'HUL BS'!G6)/2) -> 20.583828 | I19: ='HUL IS'!I8/(('HUL BS'!I6+'HUL BS'!H6)/2) -> 20.582524 | J19: ='HUL IS'!J8/(('HUL BS'!J6+'HUL BS'!I6)/2) -> 20.582524 | K19: ='HUL IS'!K8/(('HUL BS'!K6+'HUL BS'!J6)/2) -> 20.582524 | L19: ='HUL IS'!L8/(('HUL BS'!L6+'HUL BS'!K6)/2) -> 20.582524
A20: Fixed assets turnover | C20: ='HUL IS'!C8/('HUL BS'!C12) -> 0.91417686 | D20: ='HUL IS'!C8/(('HUL BS'!D12+'HUL BS'!C12)/2) -> 0.91391037 | E20: ='HUL IS'!D8/(('HUL BS'!E12+'HUL BS'!D12)/2) -> 1.0071147 | F20: ='HUL IS'!E8/(('HUL BS'!F12+'HUL BS'!E12)/2) -> 1.1384864 | G20: ='HUL IS'!F8/(('HUL BS'!G12+'HUL BS'!F12)/2) -> 1.1453844 | H20: ='HUL IS'!G8/(('HUL BS'!H12+'HUL BS'!G12)/2) -> 1.1225876 | I20: ='HUL IS'!H8/(('HUL BS'!I12+'HUL BS'!H12)/2) -> 1.176101 | J20: ='HUL IS'!I8/(('HUL BS'!J12+'HUL BS'!I12)/2) -> 1.2300345 | K20: ='HUL IS'!J8/(('HUL BS'!K12+'HUL BS'!J12)/2) -> 1.284203 | L20: ='HUL IS'!K8/(('HUL BS'!L12+'HUL BS'!K12)/2) -> 1.338418
A23: EPS | C23: ='HUL IS'!C38/'HUL BS'!C27 -> 34.042553 | D23: ='HUL IS'!D38/'HUL BS'!D27 -> 37.817021 | E23: ='HUL IS'!E38/'HUL BS'!E27 -> 43.161702 | F23: ='HUL IS'!F38/'HUL BS'!F27 -> 43.753191 | G23: ='HUL IS'!G38/'HUL BS'!G27 -> 39.744681 | H23: ='HUL IS'!H38/'HUL BS'!H27 -> 47.325119 | I23: ='HUL IS'!I38/'HUL BS'!I27 -> 50.377518 | J23: ='HUL IS'!J38/'HUL BS'!J27 -> 53.607739 | ... L23: ='HUL IS'!L38/'HUL BS'!L27 -> 60.645499
A24: P/E Ratio | H24: ='Data Sheet'!B8/'Ratio Analysis'!H23 -> 41.732594
A26: Market value of shares

Sheet CCA Analysis
A1: Comparable Companies Analysis
A2: (Amounts in Crores)
C3: Market Data | I3: Financials | M3: Valuation
A4: Company | C4: Share Price | D4: Shares Outstanding | E4: Equity Value(In crores) | F4: Net Debt(in crores) | G4: Enterprise Value ( in crores) | I4: Revenue(in crores) | J4: EBITDA(in Crores) | K4: Net Income(in crores) | M4: EV/Revenue | N4: EV/EBITDA | O4: P/E
R5: All the information is taken of FY25
A6: HUL | C6: ='Data Sheet'!B8 -> 1975 | D6: ='Data Sheet'!G53 -> 235 | E6: ='Data Sheet'!B9 -> 463997.75 | F6: ='HUL BS'!G23-'HUL BS'!G5 -> 2276 | G6: ='DCF Analysis'!E9 -> 466273.75 | I6: ='HUL IS'!H8 -> 65007.68 | J6: ='HUL IS'!H20 -> 15601.843 | K6: ='HUL IS'!H38 -> 11121.403
A7: ITC | C7: 264 | D7: 12530162791 | E7: 330473 | F7: -3727 | G7: =SUM(E7:F7) -> 326746 | I7: 75323 | J7: 25832 | K7: 41943 | M7: =G7/I7 -> 4.3379313 | N7: =G7/J7 -> 12.648885 | O7: 16.69
A8: Godrej Consumer Products | C8: 1218.7 | D8: 1023000000 | E8: 110568 | F8: 2500 | G8: =SUM(E8,F8) -> 113068 | I8: =14313 -> 14313 | J8: 3256 | K8: 1852 | M8: =G8/I8 -> 7.8996716 | N8: =G8/J8 -> 34.726044 | O8: =C8/18.19 -> 66.998351
A9: Colgate Palmolive | C9: 2350.5 | D9: 272000000 | E9: 55246 | F9: -800 | G9: =SUM(E9,F9) -> 54446 | I9: 6179 | J9: 2097 | K9: 1437 | M9: =G9/I9 -> 8.8114582 | N9: =G9/J9 -> 25.963758 | O9: =C9/49.55 -> 47.436932
A10: Dabur | C10: 535 | D10: 17723000000 | E10: 73442 | F10: 500 | G10: =SUM(E10,F10) -> 73942 | I10: 13113 | J10: 2867 | K10: 1740 | M10: =G10/I10 -> 5.6388317 | N10: =G10/J10 -> 25.790722 | O10: =C10/10.97 -> 48.769371
A11: Proctor & Gamble | C11: 6338.5 | D11: 16600000 | E11: 10106 | F11: -600 | G11: =SUM(E11,F11) -> 9506 | I11: 944.52 | J11: 328.74 | K11: 234.41 | M11: =G11/I11 -> 10.064371 | N11: =G11/J11 -> 28.916469 | O11: =C11/196.94 -> 32.184929
A13: Average | M13: =AVERAGE(M7:M11) -> 7.3504528 | N13: =AVERAGE(N7:N11) -> 25.609176 | O13: =AVERAGE(O7:O11) -> 42.415917
A14: Median | M14: =MEDIAN(M7:M11) -> 7.8996716 | N14: =MEDIAN(N7:N11) -> 25.963758 | O14: =MEDIAN(O7:O11) -> 47.436932
A16: Elvy FMCG Valuation | M16: EV/Revenue | N16: EV/EBITDA | O16: P/E
A17: Implied Enterprise Value | M17: =I6*M14 -> 513539.33 | N17: =J6*N14 -> 405082.48 | O17: =O14*K6 -> 527565.24
A18: Net Debt | M18: =-$F$6 -> -2276 | N18: =-$F$6 -> -2276 | O18: =-$F$6 -> -2276
A19: Implied Market Value | M19: =SUM(M17:M18) -> 511263.33 | N19: =SUM(N17:N18) -> 402806.48 | O19: =SUM(O17:O18) -> 525289.24
A20: Shares Outstanding | M20: =$D$6 -> 235 | N20: =$D$6 -> 235 | O20: =$D$6 -> 235
A21: Implied Value Per Share | M21: =M19/M20 -> 2175.5886 | N21: =N19/N20 -> 1714.0701 | O21: =O19/O20 -> 2235.2734
R23: in crores

Sheet Calculation Sheet
C1: Historical | D1: Historical | E1: Historical | F1: Historical | G1: Historical | H1: Projected | I1: Projected | J1: Projected | K1: Projected | L1: Projected
C2: 2021 | D2: 2022 | E2: 2023 | F2: 2024 | G2: 2025 | H2: 2026 | I2: 2027 | J2: 2028 | K2: 2029 | L2: 2030
A4: Depreciation Schedule
A5: PPE Opening | C5: 50000 | D5: =C8 -> 51443 | E5: =D8 -> 51473 | F5: =E8 -> 52678 | G5: =F8 -> 53744 | H5: =G8 -> 54335 | I5: =H8 -> 54926.855 | J5: =I8 -> 55620.928 | K5: =J8 -> 56421.684 | L5: =K8 -> 57333.897
A6: Plus Capex | C6: 2517 | D6: 1121 | E6: 2342 | F6: 2282 | G6: 1946 | H6: ='Assumption Sheet'!H17*'HUL IS'!H8 -> 1950.2304 | I6: ='Assumption Sheet'!I17*'HUL IS'!I8 -> 2067.2442 | J6: ='Assumption Sheet'!J17*'HUL IS'!J8 -> 2191.2789 | K6: ='Assumption Sheet'!K17*'HUL IS'!K8 -> 2322.7556 | L6: ='Assumption Sheet'!L17*'HUL IS'!L8 -> 2462.1209
A7: Less Depreciation | C7: -1074 | D7: -1091 | E7: -1137 | F7: -1216 | G7: -1355 | H7: =-H5*'Assumption Sheet'!H10 -> -1358.375 | I7: =-I5*'Assumption Sheet'!I10 -> -1373.1714 | J7: =-J5*'Assumption Sheet'!J10 -> -1390.5232 | K7: =-K5*'Assumption Sheet'!K10 -> -1410.5421 | L7: =-L5*'Assumption Sheet'!L10 -> -1433.3474
A8: PPE Closing | C8: =SUM(C5:C7) -> 51443 | D8: =SUM(D5:D7) -> 51473 | E8: =SUM(E5:E7) -> 52678 | F8: =SUM(F5:F7) -> 53744 | G8: =SUM(G5:G7) -> 54335 | H8: =SUM(H5:H7) -> 54926.855 | I8: =SUM(I5:I7) -> 55620.928 | J8: =SUM(J5:J7) -> 56421.684 | ... L8: =SUM(L5:L7) -> 58362.671
A12: Share capital & Retained Earnings Schedule
A14: Equity Share Capital | C14: ='Data Sheet'!C53 -> 235 | D14: ='Data Sheet'!D53 -> 235 | E14: ='Data Sheet'!E53 -> 235 | F14: ='Data Sheet'!F53 -> 235 | G14: ='Data Sheet'!G53 -> 235 | H14: 235 | I14: 235 | J14: 235 | K14: 235 | L14: 235
A16: beginning Reserves | C16: 39439 | D16: =C19 -> 47439 | E16: =D19 -> 48826 | F16: =E19 -> 50069 | G16: =F19 -> 50983 | H16: =G19 -> 51823 | I16: =H19 -> 52935.14 | J16: =I19 -> 54119.012 | K16: =J19 -> 55378.794 | L16: =K19 -> 56718.919
A17: Add: Net profit | C17: ='Data Sheet'!C25 -> 8000 | D17: 8887 | E17: 10143 | F17: 10282 | G17: 9340 | H17: ='HUL IS'!H38 -> 11121.403 | I17: ='HUL IS'!I38 -> 11838.717 | J17: ='HUL IS'!J38 -> 12597.819 | K17: ='HUL IS'!K38 -> 13401.247 | L17: ='HUL IS'!L38 -> 14251.692
A18: less Dividend paid | C18: - | D18: -7500 | E18: -8900 | F18: -9368 | G18: -8500 | H18: =-H17*'Assumption Sheet'!H20 -> -10009.263 | I18: =-I17*'Assumption Sheet'!I20 -> -10654.845 | J18: =-J17*'Assumption Sheet'!J20 -> -11338.037 | K18: =-K17*'Assumption Sheet'!K20 -> -12061.122 | L18: =-L17*'Assumption Sheet'!L20 -> -12826.523
A19: Ending Reseves&Surplus | C19: =SUM(C16:C18) -> 47439 | D19: =SUM(D16:D18) -> 48826 | E19: =SUM(E16:E18) -> 50069 | F19: =SUM(F16:F18) -> 50983 | G19: =SUM(G16:G18) -> 51823 | H19: =SUM(H16:H18) -> 52935.14 | I19: =SUM(I16:I18) -> 54119.012 | J19: =SUM(J16:J18) -> 55378.794 | ... L19: =SUM(L16:L18) -> 58144.088
A23: Formula used
A24: Enterprize value=Equity Value+Total Debt-Cash
A25: Cost of Equity= Rf+B(Rm-Rf), Where Rf is Risk free rate, Rm=Market returns
A27: EV= Equity value+Total Debt+ prefferd value-cash & cash equivallance
A28: Net Debt = Total Debt- Cash& Cash Equivallance

Sheet Valuation Summary
A1: HINDUSTAN UNILEVER LIMITED (HUL) – VALUATION SUMMARY
A2: FMVA Financial Model | Valuation overview based on DCF and Comparable Companies Analysis | ₹ crore except per share data
A4: 1. VALUATION OVERVIEW
A5: Method | B5: Implied Value / Share | C5: Vs. Market Price | D5: Valuation Signal | F5: Key Market & Reference Metrics
A6: DCF | B6: 1674.6036 | C6: -0.15209943 | D6: Downside | F6: Market Price / Share | G6: 1975
A7: CCA – EV / Revenue | B7: 2175.5886 | C7: 0.10156386 | D7: Upside | F7: CCA Central Value (avg.) | G7: 2041.644
A8: CCA – EV / EBITDA | B8: 1714.0701 | C8: -0.1321164 | D8: Downside | F8: CCA Valuation Low | G8: 1714.0701
A9: CCA – P / E | B9: 2235.2734 | C9: 0.13178398 | D9: Upside | F9: CCA Valuation High | G9: 2235.2734
A10: Market Price | B10: 1975 | C10: 0 | D10: Reference | F10: Overall Valuation Low | G10: 1674.6036
F11: Overall Valuation High | G11: 2235.2734
A12: 2. DCF KEY ASSUMPTIONS
A13: Assumption | B13: Model Value | C13: Purpose | D13: Source | F13: ILLUSTRATIVE 50 / 50 REFERENCE VALUE
A14: Long-term Growth Rate | B14: 0.05 | C14: Perpetuity growth assumption | D14: DCF Analysis | F14: Market Price / Share | G14: 1975 | H14: Vs. Market | I14: -0.059177808
A15: Exit EV / EBITDA | B15: 35.71 | C15: Terminal value cross-check | D15: DCF Analysis | F15: DCF Weight | G15: 0.5 | H15: Interpretation | I15: Implied downside
A16: WACC | B16: 0.089056816 | C16: Discount rate | D16: DCF Analysis | F16: CCA Weight | G16: 0.5 | H16: Range | I16: 1675 – 2235
A17: Cost of Debt | B17: 0.034441155 | C17: Pre-tax debt cost | D17: DCF Analysis | F17: Blended Reference Value | G17: 1858.1238 | H17: Comment | I17: Market price sits 6.3% above the blended reference value.
A18: Tax Rate | B18: 0.25 | C18: Forecast tax rate | D18: Assumption Sheet
A19: Terminal Value Method | B19: Average of Exit Multiple & Perpetuity | C19: Terminal value is averaged in model | D19: DCF Analysis
A21: 3. OPERATING OUTLOOK & VALUATION TAKEAWAYS
A22: Metric | B22: 2025A | C22: 2030F | D22: Change / CAGR | E22: Comment | F22: Model Link | H22: VALUATION CONCLUSION
A23: Revenue (₹ crore) | B23: ='HUL IS'!G8 -> 61328 | C23: ='HUL IS'!L8 -> 82070.698 | D23: 0.06 | E23: Revenue growth assumption is 6.0% p.a. in the forecast | F23: HUL IS'!A1 | H23: DCF points to a conservative value of approximately ₹1,675/share versus the model market price of ₹1,975/share, while the CCA methods range from approximately ₹1,714 to ₹2,235/share. The central CCA value is approximately ₹2,042/share. Taken together, the model indicates a broad valuation range of approximately ₹1,675–₹2,235/share. An illustrative 50/50 DCF–CCA reference value is approximately ₹1,858/share, implying about 5.9% downside to the market price. Overall, valuation appears broadly balanced, with the DCF methodology providing the more conservative anchor.
A24: EBITDA (₹ crore) | B24: ='HUL IS'!G20 -> 13058 | C24: ='HUL IS'!L20 -> 19696.968 | D24: 0.085686759 | E24: Operating scale improves with forecast revenue growth | F24: HUL IS
A25: EBITDA Margin | B25: =B24/B23 -> 0.21292069 | C25: =C24/C23 -> 0.24 | D25: 0.027079311 | E25: Model holds COGS at 50% and SG&A at 26% of revenue | F25: HUL IS
A26: Net Income (₹ crore) | B26: ='HUL IS'!G38 -> 9340 | C26: ='HUL IS'!L38 -> 14251.692 | D26: 0.08818795 | E26: Net income expands with forecast operating profit | F26: HUL IS
A27: FCF (₹ crore) | B27: ='DCF Analysis'!D20 -> 10821.506 | C27: 13592.267 | D27: 0.058646701 | E27: Positive FCF throughout forecast period supports DCF value | F27: DCF Analysis
A31: Source: Existing workbook schedules – DCF Analysis, CCA Analysis, HUL IS, HUL BS and Assumption Sheet. | H31: Note: The 50/50 blended value is an illustrative reference only and is not an input to the underlying DCF or CCA model.
